Traceback (most recent call last):
  File "/Users/francesco/.pyenv/versions/3.8.11/lib/python3.8/site-packages/jupyter_cache/executors/utils.py", line 51, in single_nb_execution
    executenb(
  File "/Users/francesco/.pyenv/versions/3.8.11/lib/python3.8/site-packages/nbclient/client.py", line 1085, in execute
    return NotebookClient(nb=nb, resources=resources, km=km, **kwargs).execute()
  File "/Users/francesco/.pyenv/versions/3.8.11/lib/python3.8/site-packages/nbclient/util.py", line 84, in wrapped
    return just_run(coro(*args, **kwargs))
  File "/Users/francesco/.pyenv/versions/3.8.11/lib/python3.8/site-packages/nbclient/util.py", line 62, in just_run
    return loop.run_until_complete(coro)
  File "/Users/francesco/.pyenv/versions/3.8.11/lib/python3.8/asyncio/base_events.py", line 616, in run_until_complete
    return future.result()
  File "/Users/francesco/.pyenv/versions/3.8.11/lib/python3.8/site-packages/nbclient/client.py", line 551, in async_execute
    await self.async_execute_cell(
  File "/Users/francesco/.pyenv/versions/3.8.11/lib/python3.8/site-packages/nbclient/client.py", line 846, in async_execute_cell
    self._check_raise_for_error(cell, exec_reply)
  File "/Users/francesco/.pyenv/versions/3.8.11/lib/python3.8/site-packages/nbclient/client.py", line 748, in _check_raise_for_error
    raise CellExecutionError.from_cell_and_msg(cell, exec_reply_content)
nbclient.exceptions.CellExecutionError: An error occurred while executing the following cell:
------------------
a=[2,3]
b=(2,3)
print("a[0] is in a list, a[0] = ",a[0],type(a))
print("b[0] is in a tuple, b[0] = ",b[0],type(b))
a[0]=5
print("We have changed the value of a[0], new value = ",a[0],type(a))
b[0]=5
print("This line will not be executed as we cannot change a tuple, b[0] =",b[0],type(b))
------------------

[0;31m---------------------------------------------------------------------------[0m
[0;31mTypeError[0m                                 Traceback (most recent call last)
[0;32m/var/folders/lt/p1n6bb0j4_173x9548b473jh0000gn/T/ipykernel_18901/1689723709.py[0m in [0;36m<module>[0;34m[0m
[1;32m      5[0m [0ma[0m[0;34m[[0m[0;36m0[0m[0;34m][0m[0;34m=[0m[0;36m5[0m[0;34m[0m[0;34m[0m[0m
[1;32m      6[0m [0mprint[0m[0;34m([0m[0;34m"We have changed the value of a[0], new value = "[0m[0;34m,[0m[0ma[0m[0;34m[[0m[0;36m0[0m[0;34m][0m[0;34m,[0m[0mtype[0m[0;34m([0m[0ma[0m[0;34m)[0m[0;34m)[0m[0;34m[0m[0;34m[0m[0m
[0;32m----> 7[0;31m [0mb[0m[0;34m[[0m[0;36m0[0m[0;34m][0m[0;34m=[0m[0;36m5[0m[0;34m[0m[0;34m[0m[0m
[0m[1;32m      8[0m [0mprint[0m[0;34m([0m[0;34m"This line will not be executed as we cannot change a tuple, b[0] ="[0m[0;34m,[0m[0mb[0m[0;34m[[0m[0;36m0[0m[0;34m][0m[0;34m,[0m[0mtype[0m[0;34m([0m[0mb[0m[0;34m)[0m[0;34m)[0m[0;34m[0m[0;34m[0m[0m

[0;31mTypeError[0m: 'tuple' object does not support item assignment
TypeError: 'tuple' object does not support item assignment

